<?xml version="1.0" ?>
<!-- =================================================================================== -->
<!-- |    This document was autogenerated by xacro from /home/mike/Documents/RobotManipulators/assignment_ws/src/my_sia20d/urdf/sia20d_dual.xacro | -->
<!-- |    EDITING THIS FILE BY HAND IS NOT RECOMMENDED                                 | -->
<!-- =================================================================================== -->
<robot name="motoman_sia20d">
    <!-- link list -->
    <link name="world" />
    <!-- link list -->
    <link name="one_base_link">
        <visual>
            <geometry>
                <mesh filename="package://motoman_sia20d_support/meshes/sia20d/visual/MOTOMAN_BASE.stl" />
            </geometry>
            <material name="">
                <color rgba="0.12941176470588237 0.14901960784313725 0.7490196078431373 1.0" />
            </material>
        </visual>
        <collision>
            <geometry>
                <mesh filename="package://motoman_sia20d_support/meshes/sia20d/collision/MOTOMAN_BASE.stl" />
            </geometry>
            <material name="">
                <color rgba="0 1 1 1" />
            </material>
        </collision>
        <inertial>
            <mass value="0.1" />
            <origin xyz="0 0 0" rpy="0 0 0" />
            <inertia ixx="0.03" iyy="0.03" izz="0.03" ixy="0.0" ixz="0.0" iyz="0.0" />
        </inertial>
    </link>
    <link name="one_link_s">
        <visual>
            <origin rpy="0 0 3.1416" xyz="0 0 0" />
            <geometry>
                <mesh filename="package://motoman_sia20d_support/meshes/sia20d/visual/MOTOMAN_AXIS_S.stl" />
            </geometry>
            <material name="">
                <color rgba="0.99 0.99 0.99 1" />
            </material>
        </visual>
        <collision>
            <origin rpy="0 0 3.1416" xyz="0 0 0" />
            <geometry>
                <mesh filename="package://motoman_sia20d_support/meshes/sia20d/collision/MOTOMAN_AXIS_S.stl" />
            </geometry>
            <material name="">
                <color rgba="0 1 1 1" />
            </material>
        </collision>
        <inertial>
            <mass value="0.1" />
            <origin xyz="0 0 0" rpy="0 0 0" />
            <inertia ixx="0.03" iyy="0.03" izz="0.03" ixy="0.0" ixz="0.0" iyz="0.0" />
        </inertial>
    </link>
    <link name="one_link_l">
        <visual>
            <origin rpy="1.57 3.1416 3.1416" xyz="0 0 0" />
            <geometry>
                <mesh filename="package://motoman_sia20d_support/meshes/sia20d/visual/MOTOMAN_AXIS_L.stl" />
            </geometry>
            <material name="">
                <color rgba="0.12941176470588237 0.14901960784313725 0.7490196078431373 1.0" />
            </material>
        </visual>
        <collision>
            <origin rpy="1.57 3.1416 3.1416" xyz="0 0 0" />
            <geometry>
                <mesh filename="package://motoman_sia20d_support/meshes/sia20d/collision/MOTOMAN_AXIS_L.stl" />
            </geometry>
            <material name="">
                <color rgba="0 1 1 1" />
            </material>
        </collision>
        <inertial>
            <mass value="0.1" />
            <origin xyz="0 0 0" rpy="0 0 0" />
            <inertia ixx="0.03" iyy="0.03" izz="0.03" ixy="0.0" ixz="0.0" iyz="0.0" />
        </inertial>
    </link>
    <link name="one_link_e">
        <visual>
            <origin rpy="0 0 0" xyz="0 0 0" />
            <geometry>
                <mesh filename="package://motoman_sia20d_support/meshes/sia20d/visual/MOTOMAN_AXIS_E.stl" />
            </geometry>
            <material name="">
                <color rgba="0.99 0.99 0.99 1" />
            </material>
        </visual>
        <collision>
            <origin rpy="0 0 0" xyz="0 0 0" />
            <geometry>
                <mesh filename="package://motoman_sia20d_support/meshes/sia20d/collision/MOTOMAN_AXIS_E.stl" />
            </geometry>
            <material name="">
                <color rgba="0 1 1 1" />
            </material>
        </collision>
        <inertial>
            <mass value="0.1" />
            <origin xyz="0 0 0" rpy="0 0 0" />
            <inertia ixx="0.03" iyy="0.03" izz="0.03" ixy="0.0" ixz="0.0" iyz="0.0" />
        </inertial>
    </link>
    <link name="one_link_u">
        <visual>
            <origin rpy="1.57 -3.1415 3.1416" xyz="0 0 0" />
            <geometry>
                <mesh filename="package://motoman_sia20d_support/meshes/sia20d/visual/MOTOMAN_AXIS_U.stl" />
            </geometry>
            <material name="">
                <color rgba="0.12941176470588237 0.14901960784313725 0.7490196078431373 1.0" />
            </material>
        </visual>
        <collision>
            <origin rpy="1.57 -3.1415 3.1416" xyz="0 0 0" />
            <geometry>
                <mesh filename="package://motoman_sia20d_support/meshes/sia20d/collision/MOTOMAN_AXIS_U.stl" />
            </geometry>
            <material name="">
                <color rgba="0 1 1 1" />
            </material>
        </collision>
        <inertial>
            <mass value="0.1" />
            <origin xyz="0 0 0" rpy="0 0 0" />
            <inertia ixx="0.03" iyy="0.03" izz="0.03" ixy="0.0" ixz="0.0" iyz="0.0" />
        </inertial>
    </link>
    <link name="one_link_r">
        <visual>
            <origin rpy="0 0 0" xyz="0 0 0" />
            <geometry>
                <mesh filename="package://motoman_sia20d_support/meshes/sia20d/visual/MOTOMAN_AXIS_R.stl" />
            </geometry>
            <material name="">
                <color rgba="0.99 0.99 0.99 1" />
            </material>
        </visual>
        <collision>
            <origin rpy="0 0 0" xyz="0 0 0" />
            <geometry>
                <mesh filename="package://motoman_sia20d_support/meshes/sia20d/collision/MOTOMAN_AXIS_R.stl" />
            </geometry>
            <material name="">
                <color rgba="0 1 1 1" />
            </material>
        </collision>
        <inertial>
            <mass value="0.1" />
            <origin xyz="0 0 0" rpy="0 0 0" />
            <inertia ixx="0.03" iyy="0.03" izz="0.03" ixy="0.0" ixz="0.0" iyz="0.0" />
        </inertial>
    </link>
    <link name="one_link_b">
        <visual>
            <origin rpy="-1.57 0 0" xyz="0 0 0" />
            <geometry>
                <mesh filename="package://motoman_sia20d_support/meshes/sia20d/visual/MOTOMAN_AXIS_B.stl" />
            </geometry>
            <material name="">
                <color rgba="0.12941176470588237 0.14901960784313725 0.7490196078431373 1.0" />
            </material>
        </visual>
        <collision>
            <origin rpy="-1.57 0 0" xyz="0 0 0" />
            <geometry>
                <mesh filename="package://motoman_sia20d_support/meshes/sia20d/collision/MOTOMAN_AXIS_B.stl" />
            </geometry>
            <material name="">
                <color rgba="0 1 1 1" />
            </material>
        </collision>
        <inertial>
            <mass value="0.1" />
            <origin xyz="0 0 0" rpy="0 0 0" />
            <inertia ixx="0.03" iyy="0.03" izz="0.03" ixy="0.0" ixz="0.0" iyz="0.0" />
        </inertial>
    </link>
    <link name="one_link_t">
        <visual>
            <geometry>
                <mesh filename="package://motoman_sia20d_support/meshes/sia20d/visual/MOTOMAN_AXIS_T.stl" />
            </geometry>
            <material name="">
                <color rgba="0.99 0.99 0.99 1" />
            </material>
        </visual>
        <collision>
            <geometry>
                <mesh filename="package://motoman_sia20d_support/meshes/sia20d/collision/MOTOMAN_AXIS_T.stl" />
            </geometry>
            <material name="">
                <color rgba="0 1 1 1" />
            </material>
        </collision>
        <inertial>
            <mass value="0.1" />
            <origin xyz="0 0 0" rpy="0 0 0" />
            <inertia ixx="0.03" iyy="0.03" izz="0.03" ixy="0.0" ixz="0.0" iyz="0.0" />
        </inertial>
    </link>
    <link name="one_tool0" />
    <!-- end of link list -->
    <!-- joint list -->
    <joint name="one_joint_s" type="revolute">
        <parent link="one_base_link" />
        <child link="one_link_s" />
        <origin rpy="0 0 0" xyz="0 0 0.41" />
        <axis xyz="0 0 1" />
        <limit effort="100" lower="-3.1415" upper="3.1415" velocity="2.2689" />
    </joint>
    <joint name="one_joint_l" type="revolute">
        <parent link="one_link_s" />
        <child link="one_link_l" />
        <origin rpy="0 0 0" xyz="0 0 0" />
        <axis xyz="0 1 0" />
        <limit effort="100" lower="-1.9198" upper="1.9198" velocity="2.2689" />
    </joint>
    <joint name="one_joint_e" type="revolute">
        <parent link="one_link_l" />
        <child link="one_link_e" />
        <origin rpy="0 0 0" xyz="0 0 0.49" />
        <axis xyz="0 0 1" />
        <limit effort="100" lower="-2.9670" upper="2.9670" velocity="2.9670" />
    </joint>
    <joint name="one_joint_u" type="revolute">
        <parent link="one_link_e" />
        <child link="one_link_u" />
        <origin rpy="0 0 0" xyz="0 0 0" />
        <axis xyz="0 -1 0" />
        <limit effort="100" lower="-2.2689" upper="2.2689" velocity="2.9670" />
    </joint>
    <joint name="one_joint_r" type="revolute">
        <parent link="one_link_u" />
        <child link="one_link_r" />
        <origin rpy="0 0 0" xyz="0 0 0.420" />
        <axis xyz="0 0 -1" />
        <limit effort="100" lower="-3.1415" upper="3.1415" velocity="3.4906" />
    </joint>
    <joint name="one_joint_b" type="revolute">
        <parent link="one_link_r" />
        <child link="one_link_b" />
        <origin rpy="0 0 0" xyz="0 0 0" />
        <axis xyz="0 -1 0" />
        <limit effort="100" lower="-1.9198" upper="1.9198" velocity="3.4906" />
    </joint>
    <joint name="one_joint_t" type="revolute">
        <parent link="one_link_b" />
        <child link="one_link_t" />
        <origin rpy="0 0 0" xyz="0 0 0.18" />
        <axis xyz="0 0 -1" />
        <limit effort="100" lower="-3.1415" upper="3.1415" velocity="6.9813" />
    </joint>
    <joint name="one_link_t-tool0" type="fixed">
        <origin rpy="0 0 -3.1415926535" xyz="0 0 0.0" />
        <parent link="one_link_t" />
        <child link="one_tool0" />
    </joint>
    <!-- end of joint list -->
    <!-- ROS base_link (via base_link) to Motoman Robot (not Base) Frame transform -->
    <link name="one_base" />
    <joint name="one_base_link-base" type="fixed">
        <origin rpy="0 0 0" xyz="0 0 0.410" />
        <parent link="one_base_link" />
        <child link="one_base" />
    </joint>
    <!--Create an instance of the right arm gripper macro-->
    <!-- BASE LINK -->
    <link name="right_gripper_base_link">
        <visual>
            <origin rpy="0 0 0" xyz="0.0 0 0" />
            <geometry>
                <mesh filename="package://wsg50_gripper/meshes/WSG50_110.stl" scale="1 1 1" />
            </geometry>
            <material name="grey">
                <color rgba="0.5 0.5 0.5 1" />
            </material>
        </visual>
        <collision>
            <origin rpy="0 0 0" xyz="0.0 0 0" />
            <geometry>
                <mesh filename="package://wsg50_gripper/meshes/WSG50_110.stl" scale="1 1 1" />
            </geometry>
        </collision>
        <inertial>
            <mass value="0.1" />
            <origin xyz="0 0 0" rpy="0 0 0" />
            <inertia ixx="0.03" iyy="0.03" izz="0.03" ixy="0.0" ixz="0.0" iyz="0.0" />
        </inertial>
    </link>
    <joint name="right_gripper_center_joint" type="fixed">
        <origin rpy="0 0 0" xyz="0 0 0.2" />
        <!--origin xyz="-0.0067 0 0.049" rpy="0 0 0" /-->
        <parent link="right_gripper_base_link" />
        <child link="right_gripper_center" />
    </joint>
    <link name="right_gripper_center" />
    <!-- GRIPPER LEFT -->
    <joint name="right_gripper_finger_left_joint" type="prismatic">
        <limit effort="1.0" lower="-0.055" upper="-0.0027" velocity="1.0" />
        <origin rpy="0 0 0" xyz="0 0 0" />
        <parent link="right_gripper_base_link" />
        <child link="right_gripper_gripper_left" />
        <!--dynamics damping="0.5" /-->
        <axis xyz="1 0 0" />
    </joint>
    <!--joint name="${name}_finger_left_joint" type="fixed">      
     <origin xyz="0 0 0" rpy="0 0 0" />
     <parent link="${name}_base_link"/>
     <child link="${name}_gripper_left" />
  </joint-->
    <link name="right_gripper_gripper_left">
        <visual>
            <origin rpy="0 0 0" xyz="0.0 0 0" />
            <geometry>
                <mesh filename="package://wsg50_gripper/meshes/GUIDE_WSG50_110.stl" scale="0.001 0.001 0.001" />
                <!--box size="0.0175 0.03 0.024"/-->
            </geometry>
            <material name="blue">
                <color rgba="0 0 1 1" />
            </material>
        </visual>
        <collision>
            <origin rpy="0 0 0" xyz="0 0 0" />
            <geometry>
                <!--box size="0.0175 0.03 0.024"/-->
                <mesh filename="package://wsg50_gripper/meshes/GUIDE_WSG50_110.stl" scale="0.001 0.001 0.001" />
            </geometry>
        </collision>
        <inertial>
            <mass value="0.1" />
            <origin xyz="0 0 0" rpy="0 0 0" />
            <inertia ixx="0.03" iyy="0.03" izz="0.03" ixy="0.0" ixz="0.0" iyz="0.0" />
        </inertial>
    </link>
    <!-- LEFT FINGER -->
    <joint name="right_gripper_guide_joint_finger_left" type="fixed">
        <origin rpy="0 0 0" xyz="0.02 0 0.2" />
        <parent link="right_gripper_gripper_left" />
        <child link="right_gripper_finger_left" />
        <axis xyz="1 0 0" />
        <limit effort="100" velocity="100" />
    </joint>
    <link name="right_gripper_finger_left">
        <visual>
            <origin rpy="0 0 0" xyz="0.0 0 0" />
            <geometry>
                <!--mesh filename="package://wsg_50_simulation/meshes/WSG-FMF.stl" scale="0.001 0.001 0.001"/-->
                <mesh filename="package://wsg50_gripper/meshes/REMODEL_finger.stl" scale="1 1 1" />
            </geometry>
            <material name="black">
                <color rgba="0 0 0 1" />
            </material>
        </visual>
        <collision>
            <!--origin xyz="0 0 0.1" rpy="0 0 0" /-->
            <origin rpy="0 0 0" xyz="0 0 0" />
            <geometry>
                <!--<mesh filename="package://wsg_50_simulation/meshes/WSG-FMF.stl" scale="0.001 0.001 0.001"/>-->
                <mesh filename="package://wsg50_gripper/meshes/REMODEL_finger.stl" scale="1 1 1" />
            </geometry>
        </collision>
        <inertial>
            <mass value="0.1" />
            <origin xyz="0 0 0" rpy="0 0 0" />
            <inertia ixx="0.03" iyy="0.03" izz="0.03" ixy="0.0" ixz="0.0" iyz="0.0" />
        </inertial>
    </link>
    <!-- GRIPPER RIGHT -->
    <joint name="right_gripper_finger_right_joint" type="prismatic">
        <limit effort="1.0" lower="0.0027" upper="0.055" velocity="1.0" />
        <origin rpy="0 0 3.14159" xyz="0 0 0" />
        <parent link="right_gripper_base_link" />
        <child link="right_gripper_gripper_right" />
        <axis xyz="-1 0 0" />
        <!--dynamics damping="0.7" friction="0.7"/-->
        <mimic joint="right_gripper_finger_left_joint" multiplier="-1.0" offset="0.0" />
        <!--dynamics damping="0.5" /-->
    </joint>
    <!--joint name="${name}_finger_right_joint" type="fixed">
     <origin xyz="0 0 0" rpy="0 0 3.14159" />
     <parent link="${name}_base_link"/>
     <child link="${name}_gripper_right" />
  </joint-->
    <link name="right_gripper_gripper_right">
        <visual>
            <origin rpy="0 0 0" xyz="0.0 0 0" />
            <geometry>
                <mesh filename="package://wsg50_gripper/meshes/GUIDE_WSG50_110.stl" scale="0.001 0.001 0.001" />
                <!--box size="0.0175 0.03 0.024"/-->
            </geometry>
            <material name="blue">
                <color rgba="0 0 1 1" />
            </material>
        </visual>
        <collision>
            <origin rpy="0 0 0" xyz="0 0 0" />
            <geometry>
                <!--box size="0.0175 0.03 0.024"/-->
                <mesh filename="package://wsg50_gripper/meshes/GUIDE_WSG50_110.stl" scale="0.001 0.001 0.001" />
            </geometry>
        </collision>
        <inertial>
            <mass value="0.1" />
            <origin xyz="0 0 0" rpy="0 0 0" />
            <inertia ixx="0.03" iyy="0.03" izz="0.03" ixy="0.0" ixz="0.0" iyz="0.0" />
        </inertial>
    </link>
    <!-- RIGHT FINGER -->
    <joint name="right_gripper_guide_joint_finger_right" type="fixed">
        <origin rpy="0 0 0" xyz="0.02 0 0.2" />
        <parent link="right_gripper_gripper_right" />
        <child link="right_gripper_finger_right" />
        <axis xyz="1 0 0" />
        <limit effort="100" velocity="100" />
    </joint>
    <link name="right_gripper_finger_right">
        <visual>
            <!--origin xyz="0.0 0 0.1" rpy="0 0 0" /-->
            <origin rpy="0 0 0" xyz="0.0 0 0" />
            <geometry>
                <!--mesh filename="package://wsg_50_simulation/meshes/WSG-FMF.stl" scale="0.001 0.001 0.001"/-->
                <mesh filename="package://wsg50_gripper/meshes/REMODEL_finger.stl" scale="1 1 1" />
            </geometry>
            <material name="black">
                <color rgba="0 0 0 1" />
            </material>
        </visual>
        <collision>
            <!--origin xyz="0 0 0.1" rpy="0 0 0" /-->
            <origin rpy="0 0 0" xyz="0 0 0" />
            <geometry>
                <!--mesh filename="package://wsg_50_simulation/meshes/WSG-FMF.stl" scale="0.001 0.001 0.001"/-->
                <mesh filename="package://wsg50_gripper/meshes/REMODEL_finger.stl" scale="1 1 1" />
            </geometry>
        </collision>
        <inertial>
            <mass value="0.1" />
            <origin xyz="0 0 0" rpy="0 0 0" />
            <inertia ixx="0.03" iyy="0.03" izz="0.03" ixy="0.0" ixz="0.0" iyz="0.0" />
        </inertial>
    </link>
    <joint name="one_world" type="fixed">
        <parent link="world" />
        <child link="one_base_link" />
        <origin rpy="0 0 0" xyz="0.7 0 0.7" />
    </joint>
    <!--Joints joining the grippers to the robot-->
    <joint name="one_tool0_gripper" type="fixed">
        <parent link="one_tool0" />
        <child link="right_gripper_base_link" />
        <!-- Make sure this matches the base link in the gripper xacro file -->
        <origin rpy="0 0 3.14159" xyz="0 0 0" />
    </joint>
    <!-- link list -->
    <link name="two_base_link">
        <visual>
            <geometry>
                <mesh filename="package://motoman_sia20d_support/meshes/sia20d/visual/MOTOMAN_BASE.stl" />
            </geometry>
            <material name="">
                <color rgba="0.12941176470588237 0.14901960784313725 0.7490196078431373 1.0" />
            </material>
        </visual>
        <collision>
            <geometry>
                <mesh filename="package://motoman_sia20d_support/meshes/sia20d/collision/MOTOMAN_BASE.stl" />
            </geometry>
            <material name="">
                <color rgba="0 1 1 1" />
            </material>
        </collision>
        <inertial>
            <mass value="0.1" />
            <origin xyz="0 0 0" rpy="0 0 0" />
            <inertia ixx="0.03" iyy="0.03" izz="0.03" ixy="0.0" ixz="0.0" iyz="0.0" />
        </inertial>
    </link>
    <link name="two_link_s">
        <visual>
            <origin rpy="0 0 3.1416" xyz="0 0 0" />
            <geometry>
                <mesh filename="package://motoman_sia20d_support/meshes/sia20d/visual/MOTOMAN_AXIS_S.stl" />
            </geometry>
            <material name="">
                <color rgba="0.99 0.99 0.99 1" />
            </material>
        </visual>
        <collision>
            <origin rpy="0 0 3.1416" xyz="0 0 0" />
            <geometry>
                <mesh filename="package://motoman_sia20d_support/meshes/sia20d/collision/MOTOMAN_AXIS_S.stl" />
            </geometry>
            <material name="">
                <color rgba="0 1 1 1" />
            </material>
        </collision>
        <inertial>
            <mass value="0.1" />
            <origin xyz="0 0 0" rpy="0 0 0" />
            <inertia ixx="0.03" iyy="0.03" izz="0.03" ixy="0.0" ixz="0.0" iyz="0.0" />
        </inertial>
    </link>
    <link name="two_link_l">
        <visual>
            <origin rpy="1.57 3.1416 3.1416" xyz="0 0 0" />
            <geometry>
                <mesh filename="package://motoman_sia20d_support/meshes/sia20d/visual/MOTOMAN_AXIS_L.stl" />
            </geometry>
            <material name="">
                <color rgba="0.12941176470588237 0.14901960784313725 0.7490196078431373 1.0" />
            </material>
        </visual>
        <collision>
            <origin rpy="1.57 3.1416 3.1416" xyz="0 0 0" />
            <geometry>
                <mesh filename="package://motoman_sia20d_support/meshes/sia20d/collision/MOTOMAN_AXIS_L.stl" />
            </geometry>
            <material name="">
                <color rgba="0 1 1 1" />
            </material>
        </collision>
        <inertial>
            <mass value="0.1" />
            <origin xyz="0 0 0" rpy="0 0 0" />
            <inertia ixx="0.03" iyy="0.03" izz="0.03" ixy="0.0" ixz="0.0" iyz="0.0" />
        </inertial>
    </link>
    <link name="two_link_e">
        <visual>
            <origin rpy="0 0 0" xyz="0 0 0" />
            <geometry>
                <mesh filename="package://motoman_sia20d_support/meshes/sia20d/visual/MOTOMAN_AXIS_E.stl" />
            </geometry>
            <material name="">
                <color rgba="0.99 0.99 0.99 1" />
            </material>
        </visual>
        <collision>
            <origin rpy="0 0 0" xyz="0 0 0" />
            <geometry>
                <mesh filename="package://motoman_sia20d_support/meshes/sia20d/collision/MOTOMAN_AXIS_E.stl" />
            </geometry>
            <material name="">
                <color rgba="0 1 1 1" />
            </material>
        </collision>
        <inertial>
            <mass value="0.1" />
            <origin xyz="0 0 0" rpy="0 0 0" />
            <inertia ixx="0.03" iyy="0.03" izz="0.03" ixy="0.0" ixz="0.0" iyz="0.0" />
        </inertial>
    </link>
    <link name="two_link_u">
        <visual>
            <origin rpy="1.57 -3.1415 3.1416" xyz="0 0 0" />
            <geometry>
                <mesh filename="package://motoman_sia20d_support/meshes/sia20d/visual/MOTOMAN_AXIS_U.stl" />
            </geometry>
            <material name="">
                <color rgba="0.12941176470588237 0.14901960784313725 0.7490196078431373 1.0" />
            </material>
        </visual>
        <collision>
            <origin rpy="1.57 -3.1415 3.1416" xyz="0 0 0" />
            <geometry>
                <mesh filename="package://motoman_sia20d_support/meshes/sia20d/collision/MOTOMAN_AXIS_U.stl" />
            </geometry>
            <material name="">
                <color rgba="0 1 1 1" />
            </material>
        </collision>
        <inertial>
            <mass value="0.1" />
            <origin xyz="0 0 0" rpy="0 0 0" />
            <inertia ixx="0.03" iyy="0.03" izz="0.03" ixy="0.0" ixz="0.0" iyz="0.0" />
        </inertial>
    </link>
    <link name="two_link_r">
        <visual>
            <origin rpy="0 0 0" xyz="0 0 0" />
            <geometry>
                <mesh filename="package://motoman_sia20d_support/meshes/sia20d/visual/MOTOMAN_AXIS_R.stl" />
            </geometry>
            <material name="">
                <color rgba="0.99 0.99 0.99 1" />
            </material>
        </visual>
        <collision>
            <origin rpy="0 0 0" xyz="0 0 0" />
            <geometry>
                <mesh filename="package://motoman_sia20d_support/meshes/sia20d/collision/MOTOMAN_AXIS_R.stl" />
            </geometry>
            <material name="">
                <color rgba="0 1 1 1" />
            </material>
        </collision>
        <inertial>
            <mass value="0.1" />
            <origin xyz="0 0 0" rpy="0 0 0" />
            <inertia ixx="0.03" iyy="0.03" izz="0.03" ixy="0.0" ixz="0.0" iyz="0.0" />
        </inertial>
    </link>
    <link name="two_link_b">
        <visual>
            <origin rpy="-1.57 0 0" xyz="0 0 0" />
            <geometry>
                <mesh filename="package://motoman_sia20d_support/meshes/sia20d/visual/MOTOMAN_AXIS_B.stl" />
            </geometry>
            <material name="">
                <color rgba="0.12941176470588237 0.14901960784313725 0.7490196078431373 1.0" />
            </material>
        </visual>
        <collision>
            <origin rpy="-1.57 0 0" xyz="0 0 0" />
            <geometry>
                <mesh filename="package://motoman_sia20d_support/meshes/sia20d/collision/MOTOMAN_AXIS_B.stl" />
            </geometry>
            <material name="">
                <color rgba="0 1 1 1" />
            </material>
        </collision>
        <inertial>
            <mass value="0.1" />
            <origin xyz="0 0 0" rpy="0 0 0" />
            <inertia ixx="0.03" iyy="0.03" izz="0.03" ixy="0.0" ixz="0.0" iyz="0.0" />
        </inertial>
    </link>
    <link name="two_link_t">
        <visual>
            <geometry>
                <mesh filename="package://motoman_sia20d_support/meshes/sia20d/visual/MOTOMAN_AXIS_T.stl" />
            </geometry>
            <material name="">
                <color rgba="0.99 0.99 0.99 1" />
            </material>
        </visual>
        <collision>
            <geometry>
                <mesh filename="package://motoman_sia20d_support/meshes/sia20d/collision/MOTOMAN_AXIS_T.stl" />
            </geometry>
            <material name="">
                <color rgba="0 1 1 1" />
            </material>
        </collision>
        <inertial>
            <mass value="0.1" />
            <origin xyz="0 0 0" rpy="0 0 0" />
            <inertia ixx="0.03" iyy="0.03" izz="0.03" ixy="0.0" ixz="0.0" iyz="0.0" />
        </inertial>
    </link>
    <link name="two_tool0" />
    <!-- end of link list -->
    <!-- joint list -->
    <joint name="two_joint_s" type="revolute">
        <parent link="two_base_link" />
        <child link="two_link_s" />
        <origin rpy="0 0 0" xyz="0 0 0.41" />
        <axis xyz="0 0 1" />
        <limit effort="100" lower="-3.1415" upper="3.1415" velocity="2.2689" />
    </joint>
    <joint name="two_joint_l" type="revolute">
        <parent link="two_link_s" />
        <child link="two_link_l" />
        <origin rpy="0 0 0" xyz="0 0 0" />
        <axis xyz="0 1 0" />
        <limit effort="100" lower="-1.9198" upper="1.9198" velocity="2.2689" />
    </joint>
    <joint name="two_joint_e" type="revolute">
        <parent link="two_link_l" />
        <child link="two_link_e" />
        <origin rpy="0 0 0" xyz="0 0 0.49" />
        <axis xyz="0 0 1" />
        <limit effort="100" lower="-2.9670" upper="2.9670" velocity="2.9670" />
    </joint>
    <joint name="two_joint_u" type="revolute">
        <parent link="two_link_e" />
        <child link="two_link_u" />
        <origin rpy="0 0 0" xyz="0 0 0" />
        <axis xyz="0 -1 0" />
        <limit effort="100" lower="-2.2689" upper="2.2689" velocity="2.9670" />
    </joint>
    <joint name="two_joint_r" type="revolute">
        <parent link="two_link_u" />
        <child link="two_link_r" />
        <origin rpy="0 0 0" xyz="0 0 0.420" />
        <axis xyz="0 0 -1" />
        <limit effort="100" lower="-3.1415" upper="3.1415" velocity="3.4906" />
    </joint>
    <joint name="two_joint_b" type="revolute">
        <parent link="two_link_r" />
        <child link="two_link_b" />
        <origin rpy="0 0 0" xyz="0 0 0" />
        <axis xyz="0 -1 0" />
        <limit effort="100" lower="-1.9198" upper="1.9198" velocity="3.4906" />
    </joint>
    <joint name="two_joint_t" type="revolute">
        <parent link="two_link_b" />
        <child link="two_link_t" />
        <origin rpy="0 0 0" xyz="0 0 0.18" />
        <axis xyz="0 0 -1" />
        <limit effort="100" lower="-3.1415" upper="3.1415" velocity="6.9813" />
    </joint>
    <joint name="two_link_t-tool0" type="fixed">
        <origin rpy="0 0 -3.1415926535" xyz="0 0 0.0" />
        <parent link="two_link_t" />
        <child link="two_tool0" />
    </joint>
    <!-- end of joint list -->
    <!-- ROS base_link (via base_link) to Motoman Robot (not Base) Frame transform -->
    <link name="two_base" />
    <joint name="two_base_link-base" type="fixed">
        <origin rpy="0 0 0" xyz="0 0 0.410" />
        <parent link="two_base_link" />
        <child link="two_base" />
    </joint>
    <!-- BASE LINK -->
    <link name="left_gripper_base_link">
        <visual>
            <origin rpy="0 0 0" xyz="0.0 0 0" />
            <geometry>
                <mesh filename="package://wsg50_gripper/meshes/WSG50_110.stl" scale="1 1 1" />
            </geometry>
            <material name="grey">
                <color rgba="0.5 0.5 0.5 1" />
            </material>
        </visual>
        <collision>
            <origin rpy="0 0 0" xyz="0.0 0 0" />
            <geometry>
                <mesh filename="package://wsg50_gripper/meshes/WSG50_110.stl" scale="1 1 1" />
            </geometry>
        </collision>
        <inertial>
            <mass value="0.1" />
            <origin xyz="0 0 0" rpy="0 0 0" />
            <inertia ixx="0.03" iyy="0.03" izz="0.03" ixy="0.0" ixz="0.0" iyz="0.0" />
        </inertial>
    </link>
    <joint name="left_gripper_center_joint" type="fixed">
        <origin rpy="0 0 0" xyz="0 0 0.2" />
        <!--origin xyz="-0.0067 0 0.049" rpy="0 0 0" /-->
        <parent link="left_gripper_base_link" />
        <child link="left_gripper_center" />
    </joint>
    <link name="left_gripper_center" />
    <!-- GRIPPER LEFT -->
    <joint name="left_gripper_finger_left_joint" type="prismatic">
        <limit effort="1.0" lower="-0.055" upper="-0.0027" velocity="1.0" />
        <origin rpy="0 0 0" xyz="0 0 0" />
        <parent link="left_gripper_base_link" />
        <child link="left_gripper_gripper_left" />
        <!--dynamics damping="0.5" /-->
        <axis xyz="1 0 0" />
    </joint>
    <!--joint name="${name}_finger_left_joint" type="fixed">      
     <origin xyz="0 0 0" rpy="0 0 0" />
     <parent link="${name}_base_link"/>
     <child link="${name}_gripper_left" />
  </joint-->
    <link name="left_gripper_gripper_left">
        <visual>
            <origin rpy="0 0 0" xyz="0.0 0 0" />
            <geometry>
                <mesh filename="package://wsg50_gripper/meshes/GUIDE_WSG50_110.stl" scale="0.001 0.001 0.001" />
                <!--box size="0.0175 0.03 0.024"/-->
            </geometry>
            <material name="blue">
                <color rgba="0 0 1 1" />
            </material>
        </visual>
        <collision>
            <origin rpy="0 0 0" xyz="0 0 0" />
            <geometry>
                <!--box size="0.0175 0.03 0.024"/-->
                <mesh filename="package://wsg50_gripper/meshes/GUIDE_WSG50_110.stl" scale="0.001 0.001 0.001" />
            </geometry>
        </collision>
        <inertial>
            <mass value="0.1" />
            <origin xyz="0 0 0" rpy="0 0 0" />
            <inertia ixx="0.03" iyy="0.03" izz="0.03" ixy="0.0" ixz="0.0" iyz="0.0" />
        </inertial>
    </link>
    <!-- LEFT FINGER -->
    <joint name="left_gripper_guide_joint_finger_left" type="fixed">
        <origin rpy="0 0 0" xyz="0.02 0 0.2" />
        <parent link="left_gripper_gripper_left" />
        <child link="left_gripper_finger_left" />
        <axis xyz="1 0 0" />
        <limit effort="100" velocity="100" />
    </joint>
    <link name="left_gripper_finger_left">
        <visual>
            <origin rpy="0 0 0" xyz="0.0 0 0" />
            <geometry>
                <!--mesh filename="package://wsg_50_simulation/meshes/WSG-FMF.stl" scale="0.001 0.001 0.001"/-->
                <mesh filename="package://wsg50_gripper/meshes/REMODEL_finger.stl" scale="1 1 1" />
            </geometry>
            <material name="black">
                <color rgba="0 0 0 1" />
            </material>
        </visual>
        <collision>
            <!--origin xyz="0 0 0.1" rpy="0 0 0" /-->
            <origin rpy="0 0 0" xyz="0 0 0" />
            <geometry>
                <!--<mesh filename="package://wsg_50_simulation/meshes/WSG-FMF.stl" scale="0.001 0.001 0.001"/>-->
                <mesh filename="package://wsg50_gripper/meshes/REMODEL_finger.stl" scale="1 1 1" />
            </geometry>
        </collision>
        <inertial>
            <mass value="0.1" />
            <origin xyz="0 0 0" rpy="0 0 0" />
            <inertia ixx="0.03" iyy="0.03" izz="0.03" ixy="0.0" ixz="0.0" iyz="0.0" />
        </inertial>
    </link>
    <!-- GRIPPER RIGHT -->
    <joint name="left_gripper_finger_right_joint" type="prismatic">
        <limit effort="1.0" lower="0.0027" upper="0.055" velocity="1.0" />
        <origin rpy="0 0 3.14159" xyz="0 0 0" />
        <parent link="left_gripper_base_link" />
        <child link="left_gripper_gripper_right" />
        <axis xyz="-1 0 0" />
        <!--dynamics damping="0.7" friction="0.7"/-->
        <mimic joint="left_gripper_finger_left_joint" multiplier="-1.0" offset="0.0" />
        <!--dynamics damping="0.5" /-->
    </joint>
    <!--joint name="${name}_finger_right_joint" type="fixed">
     <origin xyz="0 0 0" rpy="0 0 3.14159" />
     <parent link="${name}_base_link"/>
     <child link="${name}_gripper_right" />
  </joint-->
    <link name="left_gripper_gripper_right">
        <visual>
            <origin rpy="0 0 0" xyz="0.0 0 0" />
            <geometry>
                <mesh filename="package://wsg50_gripper/meshes/GUIDE_WSG50_110.stl" scale="0.001 0.001 0.001" />
                <!--box size="0.0175 0.03 0.024"/-->
            </geometry>
            <material name="blue">
                <color rgba="0 0 1 1" />
            </material>
        </visual>
        <collision>
            <origin rpy="0 0 0" xyz="0 0 0" />
            <geometry>
                <!--box size="0.0175 0.03 0.024"/-->
                <mesh filename="package://wsg50_gripper/meshes/GUIDE_WSG50_110.stl" scale="0.001 0.001 0.001" />
            </geometry>
        </collision>
        <inertial>
            <mass value="0.1" />
            <origin xyz="0 0 0" rpy="0 0 0" />
            <inertia ixx="0.03" iyy="0.03" izz="0.03" ixy="0.0" ixz="0.0" iyz="0.0" />
        </inertial>
    </link>
    <!-- RIGHT FINGER -->
    <joint name="left_gripper_guide_joint_finger_right" type="fixed">
        <origin rpy="0 0 0" xyz="0.02 0 0.2" />
        <parent link="left_gripper_gripper_right" />
        <child link="left_gripper_finger_right" />
        <axis xyz="1 0 0" />
        <limit effort="100" velocity="100" />
    </joint>
    <link name="left_gripper_finger_right">
        <visual>
            <!--origin xyz="0.0 0 0.1" rpy="0 0 0" /-->
            <origin rpy="0 0 0" xyz="0.0 0 0" />
            <geometry>
                <!--mesh filename="package://wsg_50_simulation/meshes/WSG-FMF.stl" scale="0.001 0.001 0.001"/-->
                <mesh filename="package://wsg50_gripper/meshes/REMODEL_finger.stl" scale="1 1 1" />
            </geometry>
            <material name="black">
                <color rgba="0 0 0 1" />
            </material>
        </visual>
        <collision>
            <!--origin xyz="0 0 0.1" rpy="0 0 0" /-->
            <origin rpy="0 0 0" xyz="0 0 0" />
            <geometry>
                <!--mesh filename="package://wsg_50_simulation/meshes/WSG-FMF.stl" scale="0.001 0.001 0.001"/-->
                <mesh filename="package://wsg50_gripper/meshes/REMODEL_finger.stl" scale="1 1 1" />
            </geometry>
        </collision>
        <inertial>
            <mass value="0.1" />
            <origin xyz="0 0 0" rpy="0 0 0" />
            <inertia ixx="0.03" iyy="0.03" izz="0.03" ixy="0.0" ixz="0.0" iyz="0.0" />
        </inertial>
    </link>
    <joint name="two_world" type="fixed">
        <parent link="world" />
        <child link="two_base_link" />
        <origin rpy="0 0 0" xyz="-0.7 0 0.7" />
    </joint>
    <!--Joints joining the grippers to the robot-->
    <joint name="two_tool0_gripper" type="fixed">
        <parent link="two_tool0" />
        <child link="left_gripper_base_link" />
        <!-- Make sure this matches the base link in the gripper xacro file -->
        <origin rpy="0 0 3.14159" xyz="0 0 0" />
    </joint>
    <transmission name="trans_one_joint_s">
        <type>transmission_interface/SimpleTransmission</type>
        <joint name="one_joint_s">
            <hardwareInterface>hardware_interface/EffortJointInterface</hardwareInterface>
        </joint>
        <actuator name="one_joint_s_motor">
            <hardwareInterface>hardware_interface/EffortJointInterface</hardwareInterface>
            <mechanicalReduction>1</mechanicalReduction>
        </actuator>
    </transmission>
    <transmission name="trans_one_joint_l">
        <type>transmission_interface/SimpleTransmission</type>
        <joint name="one_joint_l">
            <hardwareInterface>hardware_interface/EffortJointInterface</hardwareInterface>
        </joint>
        <actuator name="one_joint_l_motor">
            <hardwareInterface>hardware_interface/EffortJointInterface</hardwareInterface>
            <mechanicalReduction>1</mechanicalReduction>
        </actuator>
    </transmission>
    <transmission name="trans_one_joint_e">
        <type>transmission_interface/SimpleTransmission</type>
        <joint name="one_joint_e">
            <hardwareInterface>hardware_interface/EffortJointInterface</hardwareInterface>
        </joint>
        <actuator name="one_joint_e_motor">
            <hardwareInterface>hardware_interface/EffortJointInterface</hardwareInterface>
            <mechanicalReduction>1</mechanicalReduction>
        </actuator>
    </transmission>
    <transmission name="trans_one_joint_u">
        <type>transmission_interface/SimpleTransmission</type>
        <joint name="one_joint_u">
            <hardwareInterface>hardware_interface/EffortJointInterface</hardwareInterface>
        </joint>
        <actuator name="one_joint_u_motor">
            <hardwareInterface>hardware_interface/EffortJointInterface</hardwareInterface>
            <mechanicalReduction>1</mechanicalReduction>
        </actuator>
    </transmission>
    <transmission name="trans_one_joint_r">
        <type>transmission_interface/SimpleTransmission</type>
        <joint name="one_joint_r">
            <hardwareInterface>hardware_interface/EffortJointInterface</hardwareInterface>
        </joint>
        <actuator name="one_joint_r_motor">
            <hardwareInterface>hardware_interface/EffortJointInterface</hardwareInterface>
            <mechanicalReduction>1</mechanicalReduction>
        </actuator>
    </transmission>
    <transmission name="trans_one_joint_b">
        <type>transmission_interface/SimpleTransmission</type>
        <joint name="one_joint_b">
            <hardwareInterface>hardware_interface/EffortJointInterface</hardwareInterface>
        </joint>
        <actuator name="one_joint_b_motor">
            <hardwareInterface>hardware_interface/EffortJointInterface</hardwareInterface>
            <mechanicalReduction>1</mechanicalReduction>
        </actuator>
    </transmission>
    <transmission name="trans_one_joint_t">
        <type>transmission_interface/SimpleTransmission</type>
        <joint name="one_joint_t">
            <hardwareInterface>hardware_interface/EffortJointInterface</hardwareInterface>
        </joint>
        <actuator name="one_joint_t_motor">
            <hardwareInterface>hardware_interface/EffortJointInterface</hardwareInterface>
            <mechanicalReduction>1</mechanicalReduction>
        </actuator>
    </transmission>
    <transmission name="trans_right_gripper_finger_left_joint">
        <type>transmission_interface/SimpleTransmission</type>
        <joint name="right_gripper_finger_left_joint">
            <hardwareInterface>hardware_interface/EffortJointInterface</hardwareInterface>
        </joint>
        <actuator name="right_gripper_finger_left_joint_motor">
            <hardwareInterface>hardware_interface/EffortJointInterface</hardwareInterface>
            <mechanicalReduction>1</mechanicalReduction>
        </actuator>
    </transmission>
    <transmission name="trans_right_gripper_finger_right_joint">
        <type>transmission_interface/SimpleTransmission</type>
        <joint name="right_gripper_finger_right_joint">
            <hardwareInterface>hardware_interface/EffortJointInterface</hardwareInterface>
        </joint>
        <actuator name="right_gripper_finger_right_joint_motor">
            <hardwareInterface>hardware_interface/EffortJointInterface</hardwareInterface>
            <mechanicalReduction>1</mechanicalReduction>
        </actuator>
    </transmission>
    <transmission name="trans_two_joint_s">
        <type>transmission_interface/SimpleTransmission</type>
        <joint name="two_joint_s">
            <hardwareInterface>hardware_interface/EffortJointInterface</hardwareInterface>
        </joint>
        <actuator name="two_joint_s_motor">
            <hardwareInterface>hardware_interface/EffortJointInterface</hardwareInterface>
            <mechanicalReduction>1</mechanicalReduction>
        </actuator>
    </transmission>
    <transmission name="trans_two_joint_l">
        <type>transmission_interface/SimpleTransmission</type>
        <joint name="two_joint_l">
            <hardwareInterface>hardware_interface/EffortJointInterface</hardwareInterface>
        </joint>
        <actuator name="two_joint_l_motor">
            <hardwareInterface>hardware_interface/EffortJointInterface</hardwareInterface>
            <mechanicalReduction>1</mechanicalReduction>
        </actuator>
    </transmission>
    <transmission name="trans_two_joint_e">
        <type>transmission_interface/SimpleTransmission</type>
        <joint name="two_joint_e">
            <hardwareInterface>hardware_interface/EffortJointInterface</hardwareInterface>
        </joint>
        <actuator name="two_joint_e_motor">
            <hardwareInterface>hardware_interface/EffortJointInterface</hardwareInterface>
            <mechanicalReduction>1</mechanicalReduction>
        </actuator>
    </transmission>
    <transmission name="trans_two_joint_u">
        <type>transmission_interface/SimpleTransmission</type>
        <joint name="two_joint_u">
            <hardwareInterface>hardware_interface/EffortJointInterface</hardwareInterface>
        </joint>
        <actuator name="two_joint_u_motor">
            <hardwareInterface>hardware_interface/EffortJointInterface</hardwareInterface>
            <mechanicalReduction>1</mechanicalReduction>
        </actuator>
    </transmission>
    <transmission name="trans_two_joint_r">
        <type>transmission_interface/SimpleTransmission</type>
        <joint name="two_joint_r">
            <hardwareInterface>hardware_interface/EffortJointInterface</hardwareInterface>
        </joint>
        <actuator name="two_joint_r_motor">
            <hardwareInterface>hardware_interface/EffortJointInterface</hardwareInterface>
            <mechanicalReduction>1</mechanicalReduction>
        </actuator>
    </transmission>
    <transmission name="trans_two_joint_b">
        <type>transmission_interface/SimpleTransmission</type>
        <joint name="two_joint_b">
            <hardwareInterface>hardware_interface/EffortJointInterface</hardwareInterface>
        </joint>
        <actuator name="two_joint_b_motor">
            <hardwareInterface>hardware_interface/EffortJointInterface</hardwareInterface>
            <mechanicalReduction>1</mechanicalReduction>
        </actuator>
    </transmission>
    <transmission name="trans_two_joint_t">
        <type>transmission_interface/SimpleTransmission</type>
        <joint name="two_joint_t">
            <hardwareInterface>hardware_interface/EffortJointInterface</hardwareInterface>
        </joint>
        <actuator name="two_joint_t_motor">
            <hardwareInterface>hardware_interface/EffortJointInterface</hardwareInterface>
            <mechanicalReduction>1</mechanicalReduction>
        </actuator>
    </transmission>
    <transmission name="trans_left_gripper_finger_left_joint">
        <type>transmission_interface/SimpleTransmission</type>
        <joint name="left_gripper_finger_left_joint">
            <hardwareInterface>hardware_interface/EffortJointInterface</hardwareInterface>
        </joint>
        <actuator name="left_gripper_finger_left_joint_motor">
            <hardwareInterface>hardware_interface/EffortJointInterface</hardwareInterface>
            <mechanicalReduction>1</mechanicalReduction>
        </actuator>
    </transmission>
    <transmission name="trans_left_gripper_finger_right_joint">
        <type>transmission_interface/SimpleTransmission</type>
        <joint name="left_gripper_finger_right_joint">
            <hardwareInterface>hardware_interface/EffortJointInterface</hardwareInterface>
        </joint>
        <actuator name="left_gripper_finger_right_joint_motor">
            <hardwareInterface>hardware_interface/EffortJointInterface</hardwareInterface>
            <mechanicalReduction>1</mechanicalReduction>
        </actuator>
    </transmission>
    <gazebo>
        <plugin name="gazebo_ros_control" filename="libgazebo_ros_control.so">
            <robotNamespace>/</robotNamespace>
        </plugin>
    </gazebo>
</robot>

